<?xml version="1.0" ?>
<!-- =================================================================================== -->
<!-- |    This document was autogenerated by xacro from wheelchair_description.xacro   | -->
<!-- |    EDITING THIS FILE BY HAND IS NOT RECOMMENDED                                 | -->
<!-- =================================================================================== -->
<robot name="wheelchair" xmlns:xacro="http://www.ros.org/wiki/xacro">
  <!-- From front wheel right joint to front wheel left joint -->
  <!-- From front wheel joint to back wheel joint -->
  <!-- From front wheel joint to head rest -->
  <link name="base_footprint">
    <visual>
      <origin rpy="0 0 0" xyz="0 0 0"/>
      <geometry>
        <box size="0.001 0.001 0.001"/>
      </geometry>
    </visual>
  </link>
  <joint name="base_footprint_joint" type="fixed">
    <origin rpy="0 0 0" xyz=" 0 0 0.7"/>
    <parent link="base_footprint"/>
    <child link="base_link"/>
  </joint>
  <link name="base_link">
    <visual>
      <geometry>
        <box size="0.812 0.643 1.191"/>
      </geometry>
      <material name="darkgray">
        <color rgba=".2 .2 .2 1"/>
      </material>
    </visual>
    <collision>
      <geometry>
        <box size="0.812 0.643 1.191"/>
      </geometry>
    </collision>
    <inertial>
      <mass value="10.0"/>
      <inertia ixx="1.66916666667" ixy="0" ixz="0" iyy="1.2125" iyz="0" izz="1.52833333333"/>
    </inertial>
  </link>
  <link name="imu_link">
    <inertial>
      <mass value="0.01"/>
      <origin xyz="0 0 0"/>
      <inertia ixx="1.0E-6" ixy="0" ixz="0" iyy="1.0E-6" iyz="0" izz="1.0E-6"/>
    </inertial>
    <visual>
      <origin rpy="0 0 0" xyz="0 0 0"/>
      <geometry>
        <box size="0.01 0.01 0.01"/>
      </geometry>
    </visual>
  </link>
  <joint name="imu_joint" type="fixed">
    <parent link="base_link"/>
    <child link="imu_link"/>
    <origin rpy="3.14159265359 0 0" xyz="0 0 0"/>
  </joint>
  <!--Right Bar -->
  <link name="right_bar">
    <visual>
      <geometry>
        <box size="1.015 0.16075 0.148875"/>
      </geometry>
      <material name="blue">
        <color rgba="0 0 1 0.8"/>
      </material>
    </visual>
    <collision>
      <geometry>
        <box size="1.015 0.16075 0.148875"/>
      </geometry>
    </collision>
    <inertial>
      <mass value="2.0"/>
      <inertia ixx="1e-3" ixy="1e-3" ixz="1e-3" iyy="1e-3" iyz="1e-3" izz="1e-3"/>
    </inertial>
  </link>
  <joint name="right_bar_joint" type="fixed">
    <axis xyz="0 0 0"/>
    <parent link="base_link"/>
    <child link="right_bar"/>
    <origin rpy="0 0 0" xyz="0.0 0.3215 -0.446625"/>
    <!--chair_height/4 + chair_height/8 because this is relative to the center of the bar -->
  </joint>
  <!--Left Bar -->
  <link name="left_bar">
    <visual>
      <geometry>
        <box size="1.015 0.16075 0.148875"/>
      </geometry>
      <material name="blue">
        <color rgba="0 0 1 0.8"/>
      </material>
    </visual>
    <collision>
      <geometry>
        <box size="1.015 0.16075 0.148875"/>
      </geometry>
    </collision>
    <inertial>
      <mass value="2.0"/>
      <inertia ixx="1e-3" ixy="1e-3" ixz="1e-3" iyy="1e-3" iyz="1e-3" izz="1e-3"/>
    </inertial>
  </link>
  <joint name="left_bar_joint" type="fixed">
    <axis xyz="0 0 0"/>
    <parent link="base_link"/>
    <child link="left_bar"/>
    <origin rpy="0 0 0" xyz="0.0 -0.3215 -0.446625"/>
    <!--chair_height/4 + chair_height/8 because this is relative to the center of the bar -->
  </joint>
  <!--Main Wheels -->
  <joint name="right_main_wheel_joint" type="continuous">
    <axis xyz="0 0 -1"/>
    <parent link="right_bar"/>
    <child link="right_main_wheel"/>
    <origin rpy="1.57075 0 0" xyz="0.0 0.0 -0.072875"/>
  </joint>
  <link name="right_main_wheel">
    <visual>
      <geometry>
        <cylinder length="0.065" radius="0.165"/>
      </geometry>
      <material name="black">
        <color rgba="0 0 0 1"/>
      </material>
    </visual>
    <collision>
      <geometry>
        <cylinder length="0.065" radius="0.165"/>
      </geometry>
    </collision>
    <inertial>
      <mass value="2.0"/>
      <inertia ixx="0.0143166666667" ixy="0" ixz="0" iyy="0.0143166666667" iyz="0" izz="0.027225"/>
    </inertial>
  </link>
  <joint name="left_main_wheel_joint" type="continuous">
    <axis xyz="0 0 -1"/>
    <parent link="left_bar"/>
    <child link="left_main_wheel"/>
    <origin rpy="1.57075 0 0" xyz="0.0 0.0 -0.072875"/>
  </joint>
  <link name="left_main_wheel">
    <visual>
      <geometry>
        <cylinder length="0.065" radius="0.165"/>
      </geometry>
      <material name="black">
        <color rgba="0 0 0 1"/>
      </material>
    </visual>
    <collision>
      <geometry>
        <cylinder length="0.065" radius="0.165"/>
      </geometry>
    </collision>
    <inertial>
      <mass value="2.0"/>
      <inertia ixx="0.0143166666667" ixy="0" ixz="0" iyy="0.0143166666667" iyz="0" izz="0.027225"/>
    </inertial>
  </link>
  <!--Front Wheels -->
  <link name="front_right_swivel">
    <visual>
      <geometry>
        <cylinder length="0.065" radius="0.01"/>
      </geometry>
      <material name="darkgray">
        <color rgba=".2 .2 .2 1"/>
      </material>
    </visual>
    <collision>
      <geometry>
        <cylinder length="0.065" radius="0.01"/>
      </geometry>
    </collision>
    <inertial>
      <mass value=".1"/>
      <inertia ixx="3.77083333333e-05" ixy="0" ixz="0" iyy="3.77083333333e-05" iyz="0" izz="5e-06"/>
    </inertial>
  </link>
  <joint name="front_right_swivel_joint" type="continuous">
    <axis xyz="0 0 1"/>
    <parent link="right_bar"/>
    <child link="front_right_swivel"/>
    <origin rpy="0 0 0" xyz="-0.406 0.0 -0.148875"/>
    <dynamics damping="0.0" friction="0.5"/>
  </joint>
  <joint name="front_right_wheel_joint" type="continuous">
    <axis xyz="0 0 1"/>
    <parent link="front_right_swivel"/>
    <child link="front_right_wheel"/>
    <origin rpy="1.57075 0 0" xyz="0.065 0 0"/>
    <dynamics damping="0.0" friction="0.5"/>
  </joint>
  <link name="front_right_wheel">
    <visual>
      <geometry>
        <cylinder length="0.05" radius="0.089"/>
      </geometry>
      <material name="black">
        <color rgba="0 0 0 1"/>
      </material>
    </visual>
    <collision>
      <geometry>
        <cylinder length="0.05" radius="0.089"/>
      </geometry>
      <surface>
        <friction>
          <ode>
            <mu>1.0</mu>
            <mu2>1.0</mu2>
          </ode>
        </friction>
      </surface>
    </collision>
    <inertial>
      <mass value="1.0"/>
      <inertia ixx="0.00218858333333" ixy="0" ixz="0" iyy="0.00218858333333" iyz="0" izz="0.0039605"/>
    </inertial>
  </link>
  <link name="front_left_swivel">
    <visual>
      <geometry>
        <cylinder length="0.065" radius="0.01"/>
      </geometry>
      <material name="darkgray">
        <color rgba=".2 .2 .2 1"/>
      </material>
    </visual>
    <collision>
      <geometry>
        <cylinder length="0.065" radius="0.01"/>
      </geometry>
    </collision>
    <inertial>
      <mass value=".1"/>
      <inertia ixx="3.77083333333e-05" ixy="0" ixz="0" iyy="3.77083333333e-05" iyz="0" izz="5e-06"/>
    </inertial>
  </link>
  <joint name="front_left_swivel_joint" type="continuous">
    <axis xyz="0 0 1"/>
    <parent link="left_bar"/>
    <child link="front_left_swivel"/>
    <origin rpy="0 0 0" xyz="-0.406 0.0 -0.148875"/>
    <dynamics damping="0.0" friction="0.5"/>
  </joint>
  <joint name="front_left_wheel_joint" type="continuous">
    <axis xyz="0 0 1"/>
    <parent link="front_left_swivel"/>
    <child link="front_left_wheel"/>
    <origin rpy="1.57075 0 0" xyz="0.065 0 0"/>
    <dynamics damping="0" friction="0.5"/>
  </joint>
  <link name="front_left_wheel">
    <visual>
      <geometry>
        <cylinder length="0.05" radius="0.089"/>
      </geometry>
      <material name="black">
        <color rgba="0 0 0 1"/>
      </material>
    </visual>
    <collision>
      <geometry>
        <cylinder length="0.05" radius="0.089"/>
      </geometry>
      <surface>
        <friction>
          <ode>
            <mu>1.0</mu>
            <mu2>1.0</mu2>
          </ode>
        </friction>
      </surface>
    </collision>
    <inertial>
      <mass value="1.0"/>
      <inertia ixx="0.00218858333333" ixy="0" ixz="0" iyy="0.00218858333333" iyz="0" izz="0.0039605"/>
    </inertial>
  </link>
  <!--Rear Wheels -->
  <link name="rear_right_swivel">
    <visual>
      <geometry>
        <cylinder length="0.065" radius="0.01"/>
      </geometry>
      <material name="darkgray">
        <color rgba=".2 .2 .2 1"/>
      </material>
    </visual>
    <collision>
      <geometry>
        <cylinder length="0.065" radius="0.01"/>
      </geometry>
    </collision>
    <inertial>
      <mass value=".1"/>
      <inertia ixx="3.77083333333e-05" ixy="0" ixz="0" iyy="3.77083333333e-05" iyz="0" izz="5e-06"/>
    </inertial>
  </link>
  <joint name="rear_right_swivel_joint" type="continuous">
    <axis xyz="0 0 1"/>
    <parent link="right_bar"/>
    <child link="rear_right_swivel"/>
    <origin rpy="0 0 0" xyz="0.406 0.0 -0.148875"/>
    <dynamics damping="0.0" friction="0.5"/>
  </joint>
  <joint name="rear_right_wheel_joint" type="continuous">
    <axis xyz="0 0 1"/>
    <parent link="rear_right_swivel"/>
    <child link="rear_right_wheel"/>
    <origin rpy="1.57075 0 0" xyz="0.065 0 0"/>
    <dynamics damping="0" friction="0.5"/>
  </joint>
  <link name="rear_right_wheel">
    <visual>
      <geometry>
        <cylinder length="0.05" radius="0.089"/>
      </geometry>
      <material name="black">
        <color rgba="0 0 0 1"/>
      </material>
    </visual>
    <collision>
      <geometry>
        <cylinder length="0.05" radius="0.089"/>
      </geometry>
      <surface>
        <friction>
          <ode>
            <mu>1.0</mu>
            <mu2>1.0</mu2>
          </ode>
        </friction>
      </surface>
    </collision>
    <inertial>
      <mass value="1.0"/>
      <inertia ixx="0.00218858333333" ixy="0" ixz="0" iyy="0.00218858333333" iyz="0" izz="0.0039605"/>
    </inertial>
  </link>
  <link name="rear_left_swivel">
    <visual>
      <geometry>
        <cylinder length="0.065" radius="0.01"/>
      </geometry>
      <material name="darkgray">
        <color rgba=".2 .2 .2 1"/>
      </material>
    </visual>
    <collision>
      <geometry>
        <cylinder length="0.065" radius="0.01"/>
      </geometry>
    </collision>
    <inertial>
      <mass value=".1"/>
      <inertia ixx="3.77083333333e-05" ixy="0" ixz="0" iyy="3.77083333333e-05" iyz="0" izz="5e-06"/>
    </inertial>
  </link>
  <joint name="rear_left_swivel_joint" type="continuous">
    <axis xyz="0 0 1"/>
    <parent link="left_bar"/>
    <child link="rear_left_swivel"/>
    <origin rpy="0 0 0" xyz="0.406 0.0 -0.148875"/>
    <dynamics damping="0.0" friction="0.5"/>
  </joint>
  <joint name="rear_left_wheel_joint" type="continuous">
    <axis xyz="0 0 1"/>
    <parent link="rear_left_swivel"/>
    <child link="rear_left_wheel"/>
    <origin rpy="1.57075 0 0" xyz="0.065 0 0"/>
    <dynamics damping="0" friction="0.5"/>
  </joint>
  <link name="rear_left_wheel">
    <visual>
      <geometry>
        <cylinder length="0.05" radius="0.089"/>
      </geometry>
      <material name="black">
        <color rgba="0 0 0 1"/>
      </material>
    </visual>
    <collision>
      <geometry>
        <cylinder length="0.05" radius="0.089"/>
      </geometry>
      <surface>
        <friction>
          <ode>
            <mu>1.0</mu>
            <mu2>1.0</mu2>
          </ode>
        </friction>
      </surface>
    </collision>
    <inertial>
      <mass value="1.0"/>
      <inertia ixx="0.00218858333333" ixy="0" ixz="0" iyy="0.00218858333333" iyz="0" izz="0.0039605"/>
    </inertial>
  </link>
</robot>
